{
    "registryname": "test_centrifuge",
    "localizedname": "test Centrifuge",
    "parts": [
            "x": -1,
            "y": 0,
            "z": 2,
            "nbt": {"id":"minecraft:tilecolorablemachinecomponent","ForgeCaps":{"abyssalcraft:itemtransfer":{"configurations":[],"isRunning":"0b"},"nuclearcraft:capability_default_radiation_resistance":{"radiationResistance":"0.0d"}},"casingColor":"16730368"},
            "elements": [
                "modularmachinery:blockcasing@0"
            ]
        },
        {
            "x": -1,
            "y": 0,
            "z": 1,
            "nbt": {"id":"minecraft:tilecolorablemachinecomponent","ForgeCaps":{"abyssalcraft:itemtransfer":{"configurations":[],"isRunning":"0b"},"nuclearcraft:capability_default_radiation_resistance":{"radiationResistance":"0.0d"}},"casingColor":"16730368"},
            "elements": [
                "modularmachinery:blockcasing@0"
            ]
        },
        {
            "x": -1,
            "y": 0,
            "z": 0,
            "nbt": {"id":"minecraft:tileitemoutputbus","ForgeCaps":{"abyssalcraft:itemtransfer":{"configurations":[],"isRunning":"0b"},"nuclearcraft:capability_default_radiation_resistance":{"radiationResistance":"0.0d"}},"casingColor":"16730368","inventory":{"inSlots":,"outSlots":,"miscSlots":,"inventoryArray":[{"holderEmpty":"1b","holderId":"0"},{"holderEmpty":"1b","holderId":"1"},{"holderEmpty":"1b","holderId":"2"},{"holderEmpty":"1b","holderId":"3"},{"holderEmpty":"1b","holderId":"4"},{"holderEmpty":"1b","holderId":"5"},{"holderEmpty":"1b","holderId":"6"},{"holderEmpty":"1b","holderId":"7"},{"holderEmpty":"1b","holderId":"8"},{"holderEmpty":"1b","holderId":"9"},{"holderEmpty":"1b","holderId":"10"},{"holderEmpty":"1b","holderId":"11"},{"holderEmpty":"1b","holderId":"12"},{"holderEmpty":"1b","holderId":"13"},{"holderEmpty":"1b","holderId":"14"},{"holderEmpty":"1b","holderId":"15"}],"sides":},"busSize":"5"},
            "elements": [
                "modularmachinery:blockoutputbus@5"
            ]
        },
        {
            "x": 1,
            "y": 0,
            "z": 2,
            "nbt": {"id":"minecraft:tilecolorablemachinecomponent","ForgeCaps":{"abyssalcraft:itemtransfer":{"configurations":[],"isRunning":"0b"},"nuclearcraft:capability_default_radiation_resistance":{"radiationResistance":"0.0d"}},"casingColor":"16730368"},
            "elements": [
                "modularmachinery:blockcasing@0"
            ]
        },
        {
            "x": 1,
            "y": 0,
            "z": 1,
            "nbt": {"id":"minecraft:tileenergyoutputhatch","ForgeCaps":{"abyssalcraft:itemtransfer":{"configurations":[],"isRunning":"0b"},"nuclearcraft:capability_default_radiation_resistance":{"radiationResistance":"0.0d"}},"casingColor":"16730368","energy":"0L","hatchSize":"3"},
            "elements": [
                "modularmachinery:blockenergyoutputhatch@3"
            ]
        },
        {
            "x": 0,
            "y": 3,
            "z": 1,
            "nbt": {"id":"minecraft:tilecolorablemachinecomponent","ForgeCaps":{"abyssalcraft:itemtransfer":{"configurations":[],"isRunning":"0b"},"nuclearcraft:capability_default_radiation_resistance":{"radiationResistance":"0.0d"}},"casingColor":"16730368"},
            "elements": [
                "modularmachinery:blockcasing@0"
            ]
        },
        {
            "x": 1,
            "y": 0,
            "z": 0,
            "nbt": {"id":"minecraft:tileiteminputbus","ForgeCaps":{"abyssalcraft:itemtransfer":{"configurations":[],"isRunning":"0b"},"nuclearcraft:capability_default_radiation_resistance":{"radiationResistance":"0.0d"}},"casingColor":"16730368","inventory":{"inSlots":,"outSlots":,"miscSlots":,"inventoryArray":[{"holderEmpty":"1b","holderId":"0"},{"holderEmpty":"1b","holderId":"1"},{"holderEmpty":"1b","holderId":"2"},{"holderEmpty":"1b","holderId":"3"},{"holderEmpty":"1b","holderId":"4"},{"holderEmpty":"1b","holderId":"5"},{"holderEmpty":"1b","holderId":"6"},{"holderEmpty":"1b","holderId":"7"},{"holderEmpty":"1b","holderId":"8"},{"holderEmpty":"1b","holderId":"9"},{"holderEmpty":"1b","holderId":"10"},{"holderEmpty":"1b","holderId":"11"},{"holderEmpty":"1b","holderId":"12"},{"holderEmpty":"1b","holderId":"13"},{"holderEmpty":"1b","holderId":"14"},{"holderEmpty":"1b","holderId":"15"}],"sides":},"busSize":"5"},
            "elements": [
                "modularmachinery:blockinputbus@5"
            ]
        },
        {
            "x": 1,
            "y": 1,
            "z": 0,
            "nbt": {"id":"minecraft:tilecolorablemachinecomponent","ForgeCaps":{"abyssalcraft:itemtransfer":{"configurations":[],"isRunning":"0b"},"nuclearcraft:capability_default_radiation_resistance":{"radiationResistance":"0.0d"}},"casingColor":"16730368"},
            "elements": [
                "modularmachinery:blockcasing@0"
            ]
        },
        {
            "x": 1,
            "y": 1,
            "z": 2,
            "nbt": {"id":"minecraft:tilecolorablemachinecomponent","ForgeCaps":{"abyssalcraft:itemtransfer":{"configurations":[],"isRunning":"0b"},"nuclearcraft:capability_default_radiation_resistance":{"radiationResistance":"0.0d"}},"casingColor":"16730368"},
            "elements": [
                "modularmachinery:blockcasing@0"
            ]
        },
        {
            "x": 1,
            "y": 1,
            "z": 1,
            "nbt": {"id":"minecraft:tilecolorablemachinecomponent","ForgeCaps":{"abyssalcraft:itemtransfer":{"configurations":[],"isRunning":"0b"},"nuclearcraft:capability_default_radiation_resistance":{"radiationResistance":"0.0d"}},"casingColor":"16730368"},
            "elements": [
                "modularmachinery:blockcasing@0"
            ]
        },
        {
            "x": -1,
            "y": -1,
            "z": 1,
            "nbt": {"id":"minecraft:tilecolorablemachinecomponent","ForgeCaps":{"abyssalcraft:itemtransfer":{"configurations":[],"isRunning":"0b"},"nuclearcraft:capability_default_radiation_resistance":{"radiationResistance":"0.0d"}},"casingColor":"16730368"},
            "elements": [
                "modularmachinery:blockcasing@0"
            ]
        },
        {
            "x": -1,
            "y": -1,
            "z": 2,
            "nbt": {"id":"minecraft:tilecolorablemachinecomponent","ForgeCaps":{"abyssalcraft:itemtransfer":{"configurations":[],"isRunning":"0b"},"nuclearcraft:capability_default_radiation_resistance":{"radiationResistance":"0.0d"}},"casingColor":"16730368"},
            "elements": [
                "modularmachinery:blockcasing@0"
            ]
        },
        {
            "x": -1,
            "y": 1,
            "z": 2,
            "nbt": {"id":"minecraft:tilecolorablemachinecomponent","ForgeCaps":{"abyssalcraft:itemtransfer":{"configurations":[],"isRunning":"0b"},"nuclearcraft:capability_default_radiation_resistance":{"radiationResistance":"0.0d"}},"casingColor":"16730368"},
            "elements": [
                "modularmachinery:blockcasing@0"
            ]
        },
        {
            "x": -1,
            "y": 1,
            "z": 1,
            "nbt": {"id":"minecraft:tilecolorablemachinecomponent","ForgeCaps":{"abyssalcraft:itemtransfer":{"configurations":[],"isRunning":"0b"},"nuclearcraft:capability_default_radiation_resistance":{"radiationResistance":"0.0d"}},"casingColor":"16730368"},
            "elements": [
                "modularmachinery:blockcasing@0"
            ]
        },
        {
            "x": -1,
            "y": 1,
            "z": 0,
            "nbt": {"id":"minecraft:tilecolorablemachinecomponent","ForgeCaps":{"abyssalcraft:itemtransfer":{"configurations":[],"isRunning":"0b"},"nuclearcraft:capability_default_radiation_resistance":{"radiationResistance":"0.0d"}},"casingColor":"16730368"},
            "elements": [
                "modularmachinery:blockcasing@0"
            ]
        },
        {
            "x": 0,
            "y": 2,
            "z": 2,
            "nbt": {"id":"minecraft:tilecolorablemachinecomponent","ForgeCaps":{"abyssalcraft:itemtransfer":{"configurations":[],"isRunning":"0b"},"nuclearcraft:capability_default_radiation_resistance":{"radiationResistance":"0.0d"}},"casingColor":"16730368"},
            "elements": [
                "modularmachinery:blockcasing@0"
            ]
        },
        {
            "x": 0,
            "y": 2,
            "z": 1,
            "nbt": {"id":"minecraft:tilecolorablemachinecomponent","ForgeCaps":{"abyssalcraft:itemtransfer":{"configurations":[],"isRunning":"0b"},"nuclearcraft:capability_default_radiation_resistance":{"radiationResistance":"0.0d"}},"casingColor":"16730368"},
            "elements": [
                "modularmachinery:blockcasing@5"
            ]
        },
        {
            "x": 0,
            "y": 2,
            "z": 0,
            "nbt": {"id":"minecraft:tilecolorablemachinecomponent","ForgeCaps":{"abyssalcraft:itemtransfer":{"configurations":[],"isRunning":"0b"},"nuclearcraft:capability_default_radiation_resistance":{"radiationResistance":"0.0d"}},"casingColor":"16730368"},
            "elements": [
                "modularmachinery:blockcasing@0"
            ]
        },
        {
            "x": -1,
            "y": -1,
            "z": 0,
            "nbt": {"id":"minecraft:tilecolorablemachinecomponent","ForgeCaps":{"abyssalcraft:itemtransfer":{"configurations":[],"isRunning":"0b"},"nuclearcraft:capability_default_radiation_resistance":{"radiationResistance":"0.0d"}},"casingColor":"16730368"},
            "elements": [
                "modularmachinery:blockcasing@0"
            ]
        },
        {
            "x": 0,
            "y": 0,
            "z": 2,
            "nbt": {"id":"minecraft:tilecolorablemachinecomponent","ForgeCaps":{"abyssalcraft:itemtransfer":{"configurations":[],"isRunning":"0b"},"nuclearcraft:capability_default_radiation_resistance":{"radiationResistance":"0.0d"}},"casingColor":"16730368"},
            "elements": [
                "modularmachinery:blockcasing@0"
            ]
        },
        {
            "x": 0,
            "y": 0,
            "z": 1,
            "nbt": {"id":"minecraft:ec_crafting_core","ForgeCaps":{"abyssalcraft:itemtransfer":{"configurations":[],"isRunning":"0b"},"nuclearcraft:capability_default_radiation_resistance":{"radiationResistance":"0.0d"}},"Items":[],"Size":"1","Progress":"0","Energy":"0"},
            "elements": [
                "extendedcrafting:crafting_core@0"
            ]
        },
        {
            "x": -1,
            "y": 2,
            "z": 1,
            "nbt": {"id":"minecraft:tilecolorablemachinecomponent","ForgeCaps":{"abyssalcraft:itemtransfer":{"configurations":[],"isRunning":"0b"},"nuclearcraft:capability_default_radiation_resistance":{"radiationResistance":"0.0d"}},"casingColor":"16730368"},
            "elements": [
                "modularmachinery:blockcasing@0"
            ]
        },
        {
            "x": -1,
            "y": 2,
            "z": 0,
            "nbt": {"id":"minecraft:tilecolorablemachinecomponent","ForgeCaps":{"abyssalcraft:itemtransfer":{"configurations":[],"isRunning":"0b"},"nuclearcraft:capability_default_radiation_resistance":{"radiationResistance":"0.0d"}},"casingColor":"16730368"},
            "elements": [
                "modularmachinery:blockcasing@0"
            ]
        },
        {
            "x": 1,
            "y": 2,
            "z": 2,
            "nbt": {"id":"minecraft:tilecolorablemachinecomponent","ForgeCaps":{"abyssalcraft:itemtransfer":{"configurations":[],"isRunning":"0b"},"nuclearcraft:capability_default_radiation_resistance":{"radiationResistance":"0.0d"}},"casingColor":"16730368"},
            "elements": [
                "modularmachinery:blockcasing@0"
            ]
        },
        {
            "x": 1,
            "y": 2,
            "z": 1,
            "nbt": {"id":"minecraft:tilecolorablemachinecomponent","ForgeCaps":{"abyssalcraft:itemtransfer":{"configurations":[],"isRunning":"0b"},"nuclearcraft:capability_default_radiation_resistance":{"radiationResistance":"0.0d"}},"casingColor":"16730368"},
            "elements": [
                "modularmachinery:blockcasing@0"
            ]
        },
        {
            "x": 1,
            "y": 2,
            "z": 0,
            "nbt": {"id":"minecraft:tilecolorablemachinecomponent","ForgeCaps":{"abyssalcraft:itemtransfer":{"configurations":[],"isRunning":"0b"},"nuclearcraft:capability_default_radiation_resistance":{"radiationResistance":"0.0d"}},"casingColor":"16730368"},
            "elements": [
                "modularmachinery:blockcasing@0"
            ]
        },
        {
            "x": -1,
            "y": 2,
            "z": 2,
            "nbt": {"id":"minecraft:tilecolorablemachinecomponent","ForgeCaps":{"abyssalcraft:itemtransfer":{"configurations":[],"isRunning":"0b"},"nuclearcraft:capability_default_radiation_resistance":{"radiationResistance":"0.0d"}},"casingColor":"16730368"},
            "elements": [
                "modularmachinery:blockcasing@0"
            ]
        },
        {
            "x": 1,
            "y": -1,
            "z": 2,
            "nbt": {"id":"minecraft:tilecolorablemachinecomponent","ForgeCaps":{"abyssalcraft:itemtransfer":{"configurations":[],"isRunning":"0b"},"nuclearcraft:capability_default_radiation_resistance":{"radiationResistance":"0.0d"}},"casingColor":"16730368"},
            "elements": [
                "modularmachinery:blockcasing@0"
            ]
        },
        {
            "x": 0,
            "y": -1,
            "z": 0,
            "nbt": {"id":"minecraft:tilecolorablemachinecomponent","ForgeCaps":{"abyssalcraft:itemtransfer":{"configurations":[],"isRunning":"0b"},"nuclearcraft:capability_default_radiation_resistance":{"radiationResistance":"0.0d"}},"casingColor":"16730368"},
            "elements": [
                "modularmachinery:blockcasing@0"
            ]
        },
        {
            "x": 1,
            "y": -1,
            "z": 1,
            "nbt": {"id":"minecraft:tilecolorablemachinecomponent","ForgeCaps":{"abyssalcraft:itemtransfer":{"configurations":[],"isRunning":"0b"},"nuclearcraft:capability_default_radiation_resistance":{"radiationResistance":"0.0d"}},"casingColor":"16730368"},
            "elements": [
                "modularmachinery:blockcasing@0"
            ]
        },
        {
            "x": 1,
            "y": -1,
            "z": 0,
            "nbt": {"id":"minecraft:tilecolorablemachinecomponent","ForgeCaps":{"abyssalcraft:itemtransfer":{"configurations":[],"isRunning":"0b"},"nuclearcraft:capability_default_radiation_resistance":{"radiationResistance":"0.0d"}},"casingColor":"16730368"},
            "elements": [
                "modularmachinery:blockcasing@0"
            ]
        },
        {
            "x": 0,
            "y": -1,
            "z": 2,
            "nbt": {"id":"minecraft:tilecolorablemachinecomponent","ForgeCaps":{"abyssalcraft:itemtransfer":{"configurations":[],"isRunning":"0b"},"nuclearcraft:capability_default_radiation_resistance":{"radiationResistance":"0.0d"}},"casingColor":"16730368"},
            "elements": [
                "modularmachinery:blockcasing@0"
            ]
        },
        {
            "x": 0,
            "y": 1,
            "z": 1,
            "nbt": {"id":"minecraft:tilecolorablemachinecomponent","ForgeCaps":{"abyssalcraft:itemtransfer":{"configurations":[],"isRunning":"0b"},"nuclearcraft:capability_default_radiation_resistance":{"radiationResistance":"0.0d"}},"casingColor":"16730368"},
            "elements": [
                "modularmachinery:blockcasing@3"
            ]
        },
        {
            "x": 0,
            "y": 1,
            "z": 0,
            "nbt": {"id":"minecraft:tilecolorablemachinecomponent","ForgeCaps":{"abyssalcraft:itemtransfer":{"configurations":[],"isRunning":"0b"},"nuclearcraft:capability_default_radiation_resistance":{"radiationResistance":"0.0d"}},"casingColor":"16730368"},
            "elements": [
                "modularmachinery:blockcasing@0"
            ]
        },
        {
            "x": 0,
            "y": 1,
            "z": 2,
            "nbt": {"id":"minecraft:tilecolorablemachinecomponent","ForgeCaps":{"abyssalcraft:itemtransfer":{"configurations":[],"isRunning":"0b"},"nuclearcraft:capability_default_radiation_resistance":{"radiationResistance":"0.0d"}},"casingColor":"16730368"},
            "elements": [
                "modularmachinery:blockcasing@0"
            ]
        }
    ]}